Workbook
Name Account_Management_fee: '[1]Master data Input'!$C$39
Name Account_Management_fee: '[1]Master data Input'!$C$39
Name Account_Management_fee: 'Master data Input'!$C$40
Name Address: '[1]Master data Input'!$C$7
Name Address: '[1]Master data Input'!$C$7
Name Address: 'Master data Input'!$C$8
Name Advanced_Payment: '[1]Master data Input'!$F$11
Name Advanced_Payment: '[1]Master data Input'!$F$11
Name Advanced_Payment: 'Master data Input'!$C$22
Name Agent: [1]Agent!$A$1:$A$29
Name Agent: [1]Agent!$A$1:$A$29
Name Agent: Agent!$A$1:$A$30
Name Agents: '[1]Master data Input'!$F$13
Name Agents: '[1]Master data Input'!$F$13
Name Agents: 'Master data Input'!$F$14
Name Amount_of_Loan: '48 payments (computation)semi'!$B$42
Name Amount_of_Loan: '[1]Computation Sheet'!$B$43
Name Amount_of_Loan: 'Monthly -client copy'!$A$41
Name Amount_of_Loan: '[1]Computation Sheet'!$B$43
Name Amount_of_Loan: 'Semi Monthly'!$B$43
Name Amount_of_Loan: 'Semi Monthly -client copy'!$A$41
Name Amount_of_Loan: 'Semi Monthly 3 SL'!$B$43
Name Cash_Advance: '[1]Master data Input'!$E$11
Name Cash_Advance: '[1]Master data Input'!$E$11
Name Cash_Advance: 'Master data Input'!$B$22
Name choice: 'Parameter (2)'!$J$2:$J$3
Name Client_Name: '[1]Master data Input'!$C$5
Name Client_Name: '[1]Master data Input'!$C$5
Name Client_Name: 'Master data Input'!$C$6
Name Contractual_Rate: '[1](New)Amort. Sched-Diminishing'!$C$27
Name Contractual_Rate: '[1](New)Amort. Sched-Diminishing'!$C$27
Name Contractual_Rate: 'computation sheet'!$C$27
Name Date_Released: '[1]Master data Input'!$C$27
Name Date_Released: '[1]Master data Input'!$C$27
Name Date_Released: 'Master data Input'!$C$28
Name Date_Released_SM: 'Master data Input'!$K$6
Name Date_released2: '48 payments (computation)semi'!$M$13
Name Date_released2: '[1]Computation Sheet'!$M$14
Name Date_released2: 'Monthly -client copy'!$M$10
Name Date_released2: '[1]Computation Sheet'!$M$14
Name Date_released2: 'Semi Monthly'!$M$14
Name Date_released2: 'Semi Monthly -client copy'!$M$10
Name Date_released2: 'Semi Monthly 3 SL'!$M$14
Name Doc_fee: '48 payments (computation)semi'!$E$31
Name Doc_fee: 'Monthly -client copy'!#REF!
Name Doc_fee: 'Semi Monthly'!$E$32
Name Doc_fee: 'Semi Monthly -client copy'!#REF!
Name Doc_fee: 'Semi Monthly 3 SL'!$E$32
Name Docfee_Yes_or_No: '[1]Master data Input'!$C$43
Name Docfee_Yes_or_No: '[1]Master data Input'!$C$43
Name Docfee_Yes_or_No: 'Master data Input'!$C$44
Name EIR: '[1](New)Amort. Sched-Diminishing'!$C$34
Name EIR: '[1](New)Amort. Sched-Diminishing'!$C$34
Name EIR: 'Semi Monthly SL'!$C$34
Name EIR: 'computation sheet'!$C$34
Name Express: '[1]Master data Input'!$C$15
Name Express: '[1]Master data Input'!$C$15
Name Express: 'Master data Input'!$C$16
Name get_gross_amount: #REF!
Name get_gross_amount: #REF!

Sheet MENU

Sheet Master data Input
B2: LOAN COMPUTATION SHEET ver2 | I2: Semi-Monthly
B6: Name | C6: ** | D6: or | E6: ** | I6: Date Released | K6: 43265
B8: Address | C8: ** | I8: 1st payment | K8: 43317
K9: 2
B10: GROSS AMOUNT | C10: 80953.71 | E10: PN no. | F10: . | I10: Term | K10: 12
K11: 6
B12: Outstanding Balance from previous loan | C12: 0 | I12: # of Amortization | K12: 12
B14: Type of Loan | C14: SML | E14: Agent | I14: Maturity Date | K14: 43651
B16: EXPRESS | C16: NO | E16: Referal fee % | I16: Mode of Payment | K16: Monthly
B18: New | C18: No | E18: Nth Loan
B20: Mode of Payment | C20: Monthly | I20: Business Loan
B22: Cash Advance | C22: 0 | I22: Interest deduct upfront | K22: NO
B24: Add On Rate | C24: 0.03 | J24: AMOUNT | K24: 9473.68
B26: Processing Fee in Percentage | C26: 0.075
B28: Date Released | C28: 46083 | E28: =C36 -> 46342 | F28: =C36 -> 46342
B30: 1st payment | C30: 46128 | E30: 46342 | F30: 46342
B32: Term | C32: 8
B34: # of Amortization | C34: 8 | E34: Letter Signatory | G34: =IF($C$20="Semi-Monthly","<= INPUT MATURITY DATE HERE","")
B36: Maturity Date | C36: 46342 | E36: Position
B38: Notarial Fee | C38: 500 | E38: Branch
B40: Account Management fee | C40: Auto compute** | E40: Bank
B42: MLRI -Insurance | C42: Auto compute** | E42: Mode of Payment
B44: Doc Fee | C44: 500
B45: Miscellaneous | C45: 500

Sheet computation sheet
A3: COMPUTATION OF NET PROCEEDS | M3: 42632
E4: from | F4: =Date_Released -> 46083 | G4: to | H4: =MaturityDate_data_input -> 46342 | M4: 42643
A5: Loan Amount | D5: =Loan_Amount -> 80953.71 | E5: Terms in Month: | F5: =Term_masterdatainput -> 8 | G5: No. of Payments: | H5: =Monthly_Inst -> 8 | M5: =DATEDIF(M3,M4,"d") -> 11
A7: Less: Deduction: | E7: New | G7: =Renewal -> No
A8: Loan Term Adjustment | E8: Renewal Nth loan | G8: ='Master data Input'!F18 -> 0 | K8: =IF(Type_of_Loan="BL-SA",ROUND(Principal_Amount*(((Total_InterestRate/Loan_Amount)/Monthly_Inst)/30)*DATEDIF(Date_Released,MaturityDate_data_input,"d"),0),ROUND(Principal_Amount*(((Total_InterestRate/Loan_Amount)/Monthly_Inst)/30)*DATEDIF(Date_Released,Date_released2,"d"),0)) -> 0 | L8: loan term adjustment | N8: =ROUND(((((Total_InterestRate/Principal_Amount)/Monthly_Inst)*100)),2)& "% from"&TEXT(Date_Released," mm/dd/yyyy")&" to "&TEXT(Date_released2," mm/dd/yyyy") -> 2.17% from 03/02/2026 to 03/02/2026
A9: =(ROUND(Interest,4)*100&"% from"&TEXT(Date_Released," mm/dd/yyyy")&" to "&TEXT('Monthly -client copy'!Date_released2," mm/dd/yyyy")) -> 3% from 03/02/2026 to 03/17/2026 | C9: =IF(upfront="YES",'Master data Input'!K24,IF(Type_of_Loan="BL-SA",0,ROUND(Loan_Amount*(Interest/30)*DATEDIF(Date_Released,'Monthly -client copy'!Date_released2,"d"),2))) -> 1214.31 | K9: =IF(Type_of_Loan="BL-SA",ROUND(Principal_Amount*(Interest/30)*DATEDIF(Date_Released,MaturityDate_data_input,"d"),0),ROUND(Principal_Amount*(Interest/30)*DATEDIF(Date_Released,Date_released2,"d"),0)) -> 0 | L9: Advance Interest | N9: =(Interest*100) & "% from"&TEXT(Date_Released," mm/dd/yyyy")&" to "&TEXT(Date_released2," mm/dd/yyyy") -> 3% from 03/02/2026 to 03/02/2026
A10: Processing Fee | B10: =Processing_Fee_in_Percentage -> 0.075 | C10: =D5*B10 -> 6071.5283 | E10: Installment Type | G10: =Installment_Type -> Monthly
A11: Account Management Fee | C11: 0 | E11: PN. No. | G11: =PN_no. -> .
A12: Doc Fee | C12: =Docfee_Yes_or_No -> 500
A13: Notarial Fee | C13: =Notarial_Fee -> 500 | E13: MODE OF PAYMENT: | K13: =Total_UII -> 14049.306 | L13: =Interest -> 0.03 | M13: UII (old computation sheet)
A14: ='Master data Input'!B42 -> MLRI -Insurance | C14: 0 | G14: ='Master data Input'!F42 -> 0 | K14: =Total_InterestRate -> 14049.306 | L14: =((((Total_InterestRate/C26)/Monthly_Inst))) -> 0.021693426 | M14: Total Interest (deminishing)
A15: =Cash_Advance -> Cash Advance | C15: =Advanced_Payment -> 0
A16: ='Master data Input'!B45 -> Miscellaneous | C16: ='Master data Input'!C45 -> 500 | E16: Branch: | G16: ='Master data Input'!F38 -> 0 | K16: =K13-K14 -> 0 | L16: difference
A17: Previous Loan Balance | C17: =Outstanding_Balance_from_previous_loan -> 0
A18: Total Deduction | D18: =SUM(C9:C17) -> 8785.8383 | E18: Release Date: | G18: =Date_Released -> 46083
A19: Net Proceeds | D19: =D5-D18 -> 72167.872 | E19: Agent: | F19: =Agents -> 0
D22: Name | K22: Payment Frequency Options
A23: Loan Information | D23: =IF(OR_NAME<>"",Client_Name &" or " & OR_NAME,Client_Name) -> ** or ** | K23: Frequency | L23: Payments/yr | M23: Months
K24: Annual | L24: 1 | M24: 12
A25: Loan Type | C25: =Type_of_Loan -> SML | K25: Semi-Annual | L25: 2 | M25: 6
A26: Principal Amount | C26: =D5 -> 80953.71 | D26: Address | K26: Quarterly | L26: 4 | M26: 3
A27: Contractual Rate (Monthly) | C27: 0.037 | D27: =Address -> ** | K27: Bi-Monthly | L27: 6 | M27: 2
A28: No. of Monthly Installment | C28: =Number_of_Amortization -> 8 | K28: Monthly | L28: 12 | M28: 1
A29: Monthly Payment | C29: =PMT(C$27,C28,-C26)*-1 -> -11875.377 | K29: Semi-Monthly | L29: 24 | M29: 0.5
A30: Other Charges | C30: =D18 -> 8785.8383 | K30: Bi-Weekly | L30: 26 | M30: n/a
K31: Weekly | L31: 52 | M31: n/a
A32: Summary | D32: Remarks | K32: Chosen: | L32: =INDEX(L24:L31,MATCH(Installment_Type,K24:K31,0)) -> 12 | M32: =INDEX(M24:M31,MATCH(Installment_Type,K24:K31,0)) -> 1
A34: Effective Annual Interest Rate (EIR) | C34: =(1+IRR($G$41:$G$59))^Monthly_Inst-1 -> 0.661088
A35: Effective Monthly Interest Rate (MIR) | C35: =IRR($G$41:$G$59) -> 0.065489269
A36: Total Payments | C36: =SUM($G$42:$G$59) -> -95003.016
A37: Total Interest | C37: =SUM($E$40:$E$59) -> 14049.306
A39: Inst. Period | B39: Due Date | C39: Gross Loan | D39: Principal | E39: Interest | F39: Other Charges | G39: Cash Flows | H39: Balance
C40: =C26 -> 80953.71 | H40: =C26 -> 80953.71
A41: 0 | F41: =C30 -> 8785.8383 | G41: =H40-F41 -> 72167.872 | H41: =C26 -> 80953.71
A42: 1 | B42: =IF(A42="","",IF($L$32=26,(A42-1)*14+Start_Payment,IF($L$32=52,(A42-1)*7+Start_Payment,DATE(YEAR(Start_Payment),MONTH(Start_Payment)+(A42-1)*$M$32,IF($L$32=24,IF((MOD(A42-1,2))=1,DAY(Start_Payment)+15,DAY(Start_Payment)),DAY(Start_Payment)))))) -> 46128 | D42: =IF(period2<>"",E42+G42,"") -> -8880.0898 | E42: =IF(upfront="YES",0,IF(period2<>"",IF(G42<0,(H41*$C$27),0),"")) -> 2995.2873 | G42: =IF(period2<>"",IF(ROUND(H41,5)>0,C$29,0),"") -> -11875.377 | H42: =IF(period2<>"",IF(ROUND(H40,5)>0,(D42-(-H41)),0),"") -> 72073.62
A43: =IF(A42<$C$28,A42+1,"") -> 2 | B43: =IF(A43="","",IF($L$32=26,(A43-1)*14+Start_Payment,IF($L$32=52,(A43-1)*7+Start_Payment,DATE(YEAR(Start_Payment),MONTH(Start_Payment)+(A43-1)*$M$32,IF($L$32=24,IF((MOD(A43-1,2))=1,DAY(Start_Payment)+15,DAY(Start_Payment)),DAY(Start_Payment)))))) -> 46158 | D43: =IF(period2<>"",E43+G43,"") -> -9208.6531 | E43: =IF(upfront="YES",0,IF(period2<>"",IF(G43<0,(H42*$C$27),0),"")) -> 2666.7239 | G43: =IF(period2<>"",IF(ROUND(H42,5)>0,C$29,0),"") -> -11875.377 | H43: =IF(period2<>"",IF(ROUND(H41,5)>0,(D43-(-H42)),0),"") -> 62864.967
A44: =IF(A43<$C$28,A43+1,"") -> 3 | B44: =IF(A44="","",IF($L$32=26,(A44-1)*14+Start_Payment,IF($L$32=52,(A44-1)*7+Start_Payment,DATE(YEAR(Start_Payment),MONTH(Start_Payment)+(A44-1)*$M$32,IF($L$32=24,IF((MOD(A44-1,2))=1,DAY(Start_Payment)+15,DAY(Start_Payment)),DAY(Start_Payment)))))) -> 46189 | D44: =IF(period2<>"",E44+G44,"") -> -9549.3733 | E44: =IF(upfront="YES",0,IF(period2<>"",IF(G44<0,(H43*$C$27),0),"")) -> 2326.0038 | G44: =IF(period2<>"",IF(ROUND(H43,5)>0,C$29,0),"") -> -11875.377 | H44: =IF(period2<>"",IF(ROUND(H42,5)>0,(D44-(-H43)),0),"") -> 53315.594
A45: =IF(A44<$C$28,A44+1,"") -> 4 | B45: =IF(A45="","",IF($L$32=26,(A45-1)*14+Start_Payment,IF($L$32=52,(A45-1)*7+Start_Payment,DATE(YEAR(Start_Payment),MONTH(Start_Payment)+(A45-1)*$M$32,IF($L$32=24,IF((MOD(A45-1,2))=1,DAY(Start_Payment)+15,DAY(Start_Payment)),DAY(Start_Payment)))))) -> 46219 | D45: =IF(period2<>"",E45+G45,"") -> -9902.7001 | E45: =IF(upfront="YES",0,IF(period2<>"",IF(G45<0,(H44*$C$27),0),"")) -> 1972.677 | G45: =IF(period2<>"",IF(ROUND(H44,5)>0,C$29,0),"") -> -11875.377 | H45: =IF(period2<>"",IF(ROUND(H43,5)>0,(D45-(-H44)),0),"") -> 43412.894
A46: =IF(A45<$C$28,A45+1,"") -> 5 | B46: =IF(A46="","",IF($L$32=26,(A46-1)*14+Start_Payment,IF($L$32=52,(A46-1)*7+Start_Payment,DATE(YEAR(Start_Payment),MONTH(Start_Payment)+(A46-1)*$M$32,IF($L$32=24,IF((MOD(A46-1,2))=1,DAY(Start_Payment)+15,DAY(Start_Payment)),DAY(Start_Payment)))))) -> 46250 | D46: =IF(period2<>"",E46+G46,"") -> -10269.1 | E46: =IF(upfront="YES",0,IF(period2<>"",IF(G46<0,(H45*$C$27),0),"")) -> 1606.2771 | G46: =IF(period2<>"",IF(ROUND(H45,5)>0,C$29,0),"") -> -11875.377 | H46: =IF(period2<>"",IF(ROUND(H44,5)>0,(D46-(-H45)),0),"") -> 33143.794
A47: =IF(A46<$C$28,A46+1,"") -> 6 | B47: =IF(A47="","",IF($L$32=26,(A47-1)*14+Start_Payment,IF($L$32=52,(A47-1)*7+Start_Payment,DATE(YEAR(Start_Payment),MONTH(Start_Payment)+(A47-1)*$M$32,IF($L$32=24,IF((MOD(A47-1,2))=1,DAY(Start_Payment)+15,DAY(Start_Payment)),DAY(Start_Payment)))))) -> 46281 | D47: =IF(period2<>"",E47+G47,"") -> -10649.057 | E47: =IF(upfront="YES",0,IF(period2<>"",IF(G47<0,(H46*$C$27),0),"")) -> 1226.3204 | G47: =IF(period2<>"",IF(ROUND(H46,5)>0,C$29,0),"") -> -11875.377 | H47: =IF(period2<>"",IF(ROUND(H45,5)>0,(D47-(-H46)),0),"") -> 22494.737
...

Sheet Monthly -client copy
A4: =UPPER("Computation Sheet and Payment Schedule") -> COMPUTATION SHEET AND PAYMENT SCHEDULE
A5: NAME | C5: ADDRESS | E5: TYPE OF LOAN | H5: TERMS
A6: =IF(OR_NAME<>"",Client_Name &" or " & OR_NAME,Client_Name) -> ** or ** | C6: =PROPER('Master data Input'!C8) -> ** | F6: =Type_of_Loan&TEXT(IF(Express="YES","-EXPRESS",""),"") -> SML | H6: In months | I6: =Term_masterdatainput -> 8 | J6: =Terms -> 8
H7: from | I7: to
H8: =Date_Released -> 46083 | I8: =MaturityDate_data_input -> 46342 | M8: ='Master data Input'!F30 -> 46342 | N8: end of term | O8: =I6 -> 8
F9: # of payments | H9: =Number_of_Amortization -> 8
M10: =IF(U23<H8,H8,U23) -> 46098
A11: COMPUTATION OF NET PROCEEDS
W12: 7
A13: Principal/ Amount Financed | F13: ='computation sheet'!D5 -> 80953.71
A14: Less: Deduction
A15: Interest | G15: New | I15: =Renewal -> No
B16: =Interest -> 0.03 | C16: ="from"&TEXT(Date_Released," mm/dd/yyyy")&" to "&TEXT(Date_released2," mm/dd/yyyy") -> from 03/02/2026 to 03/17/2026 | E16: ='computation sheet'!C9 -> 1214.31 | G16: Renewal Nth loan | I16: ='Master data Input'!F18 -> 0 | J16: =E16+C41/A41-(360/DATEDIF(H8,I8,"d")) -> 1213.0936 | L16: =DATEDIF(H8,B46,"d") -> 45 | M16: days from loan release and 1st payment
A17: Processing Fee | C17: =Processing_Fee_in_Percentage -> 0.075 | E17: =Principal_Amount*Percent_processingfee -> 6071.5283 | G17: Installment Type | I17: =Installment_Type -> Monthly | L17: =DATEDIF(H8,M10,"D") -> 15
A18: Account Management Fee | E18: ='computation sheet'!C11 -> 0
A19: Doc fee | E19: =Docfee_Yes_or_No -> 500
A20: Notarial fee | E20: =Notarial_Fee -> 500 | G20: Check No.
A21: ='Master data Input'!B42 -> MLRI -Insurance | E21: ='computation sheet'!C14 -> 0
A22: ='Master data Input'!B45 -> Miscellaneous | E22: ='Master data Input'!C45 -> 500 | L22: =DATEDIF(M10,M8,"D") -> 244
A23: Total Finance charge | E23: =SUM(E16:E22) -> 8785.8383 | G23: PN no. | H23: ="PN-"&TEXT('Master data Input'!F10,"0000- ")&TEXT(" "," ")&'Master data Input'!C14 -> PN-. SML | L23: =DATEDIF(H8,M8,"D") -> 259 | U23: =DATE(YEAR(B46),MONTH(B46),DAY(B46)-30) -> 46098
A25: Others: | G25: Branch: | H25: ='Master data Input'!F38 -> 0 | P25: =TEXT($L$16,"0")&"/"&TEXT($L$17,"0")&"/"&TEXT($L$22,"0")&"/"&TEXT($L$23,"0") -> 45/15/244/259 | X25: =45000*0.15*(305/360) -> 5718.75
A26: =Cash_Advance -> Cash Advance | E26: =Advanced_Payment -> 0 | L26: =DATEDIF(M10,B46,"d") -> 30
A27: ='Master data Input'!B12 -> Outstanding Balance from previous loan | E27: =Outstanding_Balance_from_previous_loan -> 0
F28: =Total_Finance_Charge+SUM($E$26:$E$28) -> 8785.8383
G29: MODE OF PAYMENT: | I29: ='Master data Input'!F42 -> 0
A30: Net Proceeds | F30: =Principal_Amount-Total_Deduction -> 72167.872
M31: IF('Master data Input'!B35="YES",ROUNDUP(F16*0.0015,0),"0") | U31: DATEDIF(H11,I11,"D")
A32: % of Finance charges to Total Amount Financed | F32: =Total_Finance_Charge/Principal_Amount -> 0.10852916
A33: Contractual Interest Rate per Month | F33: =Contractual_Rate -> 0.037
A34: Equivalent Add-on Interest Rate per Month | F34: =Interest -> 0.03
A35: Effective Annual Rate (EIR) | F35: =EIR -> 0.661088 | M35: IF(1200>O27,1200,O27)
A36: Effective Monthly Interest Rate (MIR) | F36: =MIR -> 0.065489269 | G36: Release Date: | I36: =Date_Released -> 46083
G37: Agent: | H37: =UPPER(Agents)
A38: SCHEDULE OF PAYMENT
N39: =C41+E16 -> 15263.616 | O39: 11667
A40: Principal / Amount of Loan | C40: Interest Due on Loans | E40: Total Amount Payable | X40: =DATE(YEAR(U17),MONTH(U17)+1,DAY(U17)) -> 31
A41: =Principal_Amount -> 80953.71 | C41: ='computation sheet'!C37 -> 14049.306 | E41: =IF(Type_of_Loan="BL-SA",Amount_of_Loan,Loan_Amount+Total_UII) -> 95003.016 | J41: =DATE(YEAR($B$46),MONTH($B$46)+($H$9-1),DAY($B$46)) -> 46342 | K41: w/out adjustment
A43: Period | B43: Due Date | C43: Gross Loan | D43: Amortization | E43: Interest | F43: Principal | G43: Other Charges | I43: Balance
C44: =Loan_Amount -> 80953.71 | I44: =Loan_Amount -> 80953.71
A45: 0 | G45: ='Monthly -client copy'!Total_Deduction -> 8785.8383 | I45: =Loan_Amount -> 80953.71
...

Sheet Semi Monthly SL
A3: COMPUTATION OF NET PROCEEDS
E4: from | F4: =Date_Released_SM -> 43265 | G4: to | H4: =Maturitydate_SM -> 43651
A5: Loan Amount | D5: =IF(get_loan_amount="NET AMOUNT",get_gross_amount,Loan_Amount) -> 80953.71 | E5: Terms in Month: | F5: =DATEDIF(Date_Released,Maturitydate_SM,"d")/30 -> #NUM! | G5: No. of Payments: | H5: =Monthly_Inst -> 12
A7: Less: Deduction: | E7: New | G7: =IF(G8>=0,"NO", "YES") -> NO
A8: Loan Term Adjustment | E8: Renewal Nth loan | G8: =Renewal -> No | K8: =IF(Type_of_Loan="BL-SA",ROUND(Principal_Amount*(((Total_InterestRate/Loan_Amount)/Monthly_Inst)/30)*DATEDIF(Date_Released,MaturityDate_data_input,"d"),0),ROUND(Principal_Amount*(((Total_InterestRate/Loan_Amount)/Monthly_Inst)/30)*DATEDIF(Date_Released,Date_released2,"d"),0)) -> 0 | L8: loan term adjustment | N8: =ROUND(((((Total_InterestRate/Principal_Amount)/Monthly_Inst)*100)),2)& "% from"&TEXT(Date_Released," mm/dd/yyyy")&" to "&TEXT(Date_released2," mm/dd/yyyy") -> 1.45% from 03/02/2026 to 03/02/2026
A9: =(ROUND(Interest,3)*100&"% from"&TEXT(Date_Released," mm/dd/yyyy")&" to "&TEXT(Date_released2," mm/dd/yyyy")) -> 3% from 03/02/2026 to 03/02/2026 | C9: =IF(Type_of_Loan="SL",0,ROUND(Principal_Amount*(Interest/30)*DATEDIF(Date_Released,Date_released2,"d"),2)) -> 0 | K9: =IF(Type_of_Loan="BL-SA",ROUND(Principal_Amount*(Interest/30)*DATEDIF(Date_Released,MaturityDate_data_input,"d"),0),ROUND(Principal_Amount*(Interest/30)*DATEDIF(Date_Released,Date_released2,"d"),0)) -> 0 | L9: Advance Interest | N9: =(Interest*100) & "% from"&TEXT(Date_Released," mm/dd/yyyy")&" to "&TEXT(Date_released2," mm/dd/yyyy") -> 3% from 03/02/2026 to 03/02/2026
A10: Processing Fee | B10: =Processing_Fee_in_Percentage -> 0.075 | C10: =D5*B10 -> 6071.5283 | E10: Installment Type | G10: Semi Monthly
A11: Account Management Fee | C11: =Account_Management_fee -> Auto compute** | E11: PN. No. | G11: =PN_no. -> .
A12: Doc Fee | C12: =Docfee_Yes_or_No -> 500
A13: Notarial Fee | C13: =Notarial_Fee -> 500 | E13: MODE OF PAYMENT: | K13: =Total_UII -> 14049.306 | L13: =Interest -> 0.03 | M13: UII (old computation sheet)
A14: ='Master data Input'!B42 -> MLRI -Insurance | C14: =Insurance -> Auto compute** | G14: ='Master data Input'!F42 -> 0 | K14: =Total_InterestRate -> 14049.306 | L14: =((((Total_InterestRate/C26)/Monthly_Inst))) -> 0.014462284 | M14: Total Interest (deminishing)
A15: =Cash_Advance -> Cash Advance | C15: =Advanced_Payment -> 0
A16: ='Master data Input'!B45 -> Miscellaneous | C16: ='Master data Input'!C45 -> 500 | E16: Branch: | G16: ='Master data Input'!F38 -> 0 | K16: =K13-K14 -> 0 | L16: difference
A17: Previous Loan Balance | C17: =Outstanding_Balance_from_previous_loan -> 0
A18: Total Deduction | D18: =SUM(C9:C17) -> 7571.5283 | E18: Release Date: | G18: =Date_Released -> 46083
A19: Net Proceeds | D19: =D5-D18 -> 73382.182 | E19: Agent: | F19: =Agents -> 0
D22: Name | K22: Payment Frequency Options
A23: Loan Information | D23: =IF(OR_NAME<>"",Client_Name &" or " & OR_NAME,Client_Name) -> ** or ** | K23: Frequency | L23: Payments/yr | M23: Months
K24: Annual | L24: 1 | M24: 12
A25: Loan Type | C25: =Type_of_Loan -> SML | K25: Semi-Annual | L25: 2 | M25: 6
A26: Principal Amount | C26: =D5 -> 80953.71 | D26: Address | K26: Quarterly | L26: 4 | M26: 3
A27: Contractual Rate (Monthly) | C27: =Contractual_Rate -> 0.037 | D27: =Address -> ** | K27: Bi-Monthly | L27: 6 | M27: 2
A28: No. of Monthly Installment | C28: ='Master data Input'!K12 -> 12 | K28: Monthly | L28: 12 | M28: 1
A29: Monthly Payment | C29: ='Monthly -client copy'!D67/'Semi Monthly -client copy'!H9 -> 7916.918 | K29: Semi-Monthly | L29: 24 | M29: 0.5
A30: Other Charges | C30: =D18 -> 7571.5283 | K30: Bi-Weekly | L30: 26 | M30: n/a
K31: Weekly | L31: 52 | M31: n/a
A32: Summary | D32: Remarks | K32: Chosen: | L32: =INDEX(L24:L31,MATCH(Installment_Type_SM,K24:K31,0)) -> 24 | M32: =INDEX(M24:M31,MATCH(Installment_Type_SM,K24:K31,0)) -> 0.5
A34: Effective Annual Interest Rate (EIR) | C34: =(1+IRR($G$41:$G$59))^12-1 -> #NUM!
A35: Effective Monthly Interest Rate (MIR) | C35: =IRR($G$41:$G$59) -> #NUM!
A36: Total Payments | C36: =SUM($G$42:$G$59) -> 95003.016
A37: Total Interest | C37: =Total_InterestRate -> 14049.306
A39: Inst. Period | B39: Due Date | C39: Gross Loan | D39: Principal | E39: Interest | F39: Other Charges | G39: Cash Flows | H39: Balance
C40: =C26 -> 80953.71 | H40: =C26 -> 80953.71
A41: 0 | F41: =C30 -> 7571.5283 | G41: =H40-F41 -> 73382.182 | H41: =C26 -> 80953.71
A42: 1 | B42: =IF(A42="","",IF($L$32=26,(A42-1)*14+Start_Payment_SM,IF($L$32=52,(A42-1)*7+Start_Payment_SM,DATE(YEAR(Start_Payment_SM),MONTH(Start_Payment_SM)+(A42-1)*$M$32,IF($L$32=24,IF((MOD(A42-1,2))=1,DAY(Start_Payment_SM)+15,DAY(Start_Payment_SM)),DAY(Start_Payment_SM)))))) -> 43317 | D42: =IF(period2<>"",E42+G42,"") -> 7916.918 | E42: =IF(period2<>"",IF(G42<0,(H41*$C$27),0),"") -> 0 | G42: =IF(period2<>"",IF(ROUND(H41,5)>0,C$29,0),"") -> 7916.918 | H42: =IF(period2<>"",IF(ROUND(H40,5)>0,(D42-(-H41)),0),"") -> 88870.628
A43: =IF(A42<$C$28,A42+1,"") -> 2 | B43: =IF(A43="","",IF($L$32=26,(A43-1)*14+Start_Payment_SM,IF($L$32=52,(A43-1)*7+Start_Payment_SM,DATE(YEAR(Start_Payment_SM),MONTH(Start_Payment_SM)+(A43-1)*$M$32,IF($L$32=24,IF((MOD(A43-1,2))=1,DAY(Start_Payment_SM)+15,DAY(Start_Payment_SM)),DAY(Start_Payment_SM)))))) -> 43332 | D43: =IF(period2<>"",E43+G43,"") -> 7916.918 | E43: =IF(period2<>"",IF(G43<0,(H42*$C$27),0),"") -> 0 | G43: =IF(period2<>"",IF(ROUND(H42,5)>0,C$29,0),"") -> 7916.918 | H43: =IF(period2<>"",IF(ROUND(H41,5)>0,(D43-(-H42)),0),"") -> 96787.546
A44: =IF(A43<$C$28,A43+1,"") -> 3 | B44: =IF(A44="","",IF($L$32=26,(A44-1)*14+Start_Payment_SM,IF($L$32=52,(A44-1)*7+Start_Payment_SM,DATE(YEAR(Start_Payment_SM),MONTH(Start_Payment_SM)+(A44-1)*$M$32,IF($L$32=24,IF((MOD(A44-1,2))=1,DAY(Start_Payment_SM)+15,DAY(Start_Payment_SM)),DAY(Start_Payment_SM)))))) -> 43348 | D44: =IF(period2<>"",E44+G44,"") -> 7916.918 | E44: =IF(period2<>"",IF(G44<0,(H43*$C$27),0),"") -> 0 | G44: =IF(period2<>"",IF(ROUND(H43,5)>0,C$29,0),"") -> 7916.918 | H44: =IF(period2<>"",IF(ROUND(H42,5)>0,(D44-(-H43)),0),"") -> 104704.46
A45: =IF(A44<$C$28,A44+1,"") -> 4 | B45: =IF(A45="","",IF($L$32=26,(A45-1)*14+Start_Payment_SM,IF($L$32=52,(A45-1)*7+Start_Payment_SM,DATE(YEAR(Start_Payment_SM),MONTH(Start_Payment_SM)+(A45-1)*$M$32,IF($L$32=24,IF((MOD(A45-1,2))=1,DAY(Start_Payment_SM)+15,DAY(Start_Payment_SM)),DAY(Start_Payment_SM)))))) -> 43363 | D45: =IF(period2<>"",E45+G45,"") -> 7916.918 | E45: =IF(period2<>"",IF(G45<0,(H44*$C$27),0),"") -> 0 | G45: =IF(period2<>"",IF(ROUND(H44,5)>0,C$29,0),"") -> 7916.918 | H45: =IF(period2<>"",IF(ROUND(H43,5)>0,(D45-(-H44)),0),"") -> 112621.38
A46: =IF(A45<$C$28,A45+1,"") -> 5 | B46: =IF(A46="","",IF($L$32=26,(A46-1)*14+Start_Payment_SM,IF($L$32=52,(A46-1)*7+Start_Payment_SM,DATE(YEAR(Start_Payment_SM),MONTH(Start_Payment_SM)+(A46-1)*$M$32,IF($L$32=24,IF((MOD(A46-1,2))=1,DAY(Start_Payment_SM)+15,DAY(Start_Payment_SM)),DAY(Start_Payment_SM)))))) -> 43378 | D46: =IF(period2<>"",E46+G46,"") -> 7916.918 | E46: =IF(period2<>"",IF(G46<0,(H45*$C$27),0),"") -> 0 | G46: =IF(period2<>"",IF(ROUND(H45,5)>0,C$29,0),"") -> 7916.918 | H46: =IF(period2<>"",IF(ROUND(H44,5)>0,(D46-(-H45)),0),"") -> 120538.3
A47: =IF(A46<$C$28,A46+1,"") -> 6 | B47: =IF(A47="","",IF($L$32=26,(A47-1)*14+Start_Payment_SM,IF($L$32=52,(A47-1)*7+Start_Payment_SM,DATE(YEAR(Start_Payment_SM),MONTH(Start_Payment_SM)+(A47-1)*$M$32,IF($L$32=24,IF((MOD(A47-1,2))=1,DAY(Start_Payment_SM)+15,DAY(Start_Payment_SM)),DAY(Start_Payment_SM)))))) -> 43393 | D47: =IF(period2<>"",E47+G47,"") -> 7916.918 | E47: =IF(period2<>"",IF(G47<0,(H46*$C$27),0),"") -> 0 | G47: =IF(period2<>"",IF(ROUND(H46,5)>0,C$29,0),"") -> 7916.918 | H47: =IF(period2<>"",IF(ROUND(H45,5)>0,(D47-(-H46)),0),"") -> 128455.22
...

Sheet Semi Monthly 3 SL
A4: 9th Floor Times Plaza Bldg., UN Ave. Cor. Taft Ave. Ermita Manila
A5: Manila, Philippines
A6: 353-85-24/25
A8: =UPPER("Computation Sheet and Payment Schedule") -> COMPUTATION SHEET AND PAYMENT SCHEDULE
A9: NAME | C9: ADDRESS | E9: TYPE OF LOAN | H9: TERMS
A10: =IF(OR_NAME<>"",Client_Name &" or " & OR_NAME,Client_Name) -> ** or ** | C10: =PROPER('Master data Input'!C8) -> ** | F10: =Type_of_Loan&TEXT(IF(Express="YES","-EXPRESS",""),"") -> SML | H10: In months | I10: =Term_masterdatainput -> 8 | J10: =Terms -> 8
F11: Interest/mo | G11: =Interest -> 0.03 | H11: from | I11: to
A12: =IF(UPPER(OR_NAME)<>" ",UPPER(OR_NAME),".") -> ** | H12: =Date_Released -> 46083 | I12: =MaturityDate_data_input -> 46342 | M12: ='Master data Input'!F30 -> 46342 | N12: end of term | O12: =I10 -> 8
F13: # of payments | G13: ='Semi Monthly SL'!Monthly_Inst -> 12
M14: =IF(U27<H12,H12,U27) -> 46083
A15: COMPUTATION OF NET PROCEEDS
W16: 7
A17: Principal/ Amount Financed | F17: =IF(get_loan_amount="NET AMOUNT",get_gross_amount,Loan_Amount) -> 80953.71
A19: Less Interest and Other Charges | G19: New | I19: =IF(I20>0,"NO", "YES") -> NO
A20: Interest | B20: =Interest -> 0.03 | C20: ="from"&TEXT(Date_Released," mm/dd/yyyy")&" to "&TEXT(Date_released2," mm/dd/yyyy") -> from 03/02/2026 to 03/02/2026 | E20: =IF(Type_of_Loan="BL-SA",0,ROUND(Principal_Amount*(Interest/30)*DATEDIF(Date_Released,Date_released2,"d"),2)) -> 0 | G20: Renewal Nth loan | I20: ='Master data Input'!C18 -> No | J20: =E20+D43/B43-(360/DATEDIF(H12,I12,"d")) -> #DIV/0! | L20: =DATEDIF(H12,C45,"d") -> #NUM! | M20: days from loan release and 1st payment
A21: Processing Fee | C21: =Processing_Fee_in_Percentage -> 0.075 | E21: =Principal_Amount*Percent_processingfee -> 6071.5283 | G21: Installment Type | I21: =Installment_Type -> Monthly | L21: =DATEDIF(H12,M14,"D") -> 0
A22: Account Management Fee | E22: =Account_Management_fee -> Auto compute**
A23: Notarial fee | E23: =Notarial_Fee -> 500
A24: Doc fee | E24: =Docfee_Yes_or_No -> 500
A25: ='Master data Input'!B42 -> MLRI -Insurance | E25: =Insurance -> Auto compute**
A26: ='Master data Input'!B45 -> Miscellaneous | E26: ='Master data Input'!C45 -> 500 | G26: Check No. | L26: =DATEDIF(M14,M12,"D") -> 259
A27: Total Finance charge | E27: =SUM(E20:E26) -> 7571.5283 | L27: =DATEDIF(H12,M12,"D") -> 259 | U27: =DATE(YEAR(C45),MONTH(C45),DAY(C45)-30) -> 42621
A28: Others: | G28: PN no. | H28: ="PN-"&TEXT('Master data Input'!F10,"0000- ")&TEXT(" "," ")&'Master data Input'!C14 -> PN-. SML
A29: ='Master data Input'!B12 -> Outstanding Balance from previous loan | E29: =Outstanding_Balance_from_previous_loan -> 0 | P29: =TEXT($L$20,"0")&"/"&TEXT($L$21,"0")&"/"&TEXT($L$26,"0")&"/"&TEXT($L$27,"0") -> #NUM! | X29: =45000*0.15*(305/360) -> 5718.75
A30: Cash Advance | E30: =Advanced_Payment -> 0 | L30: =DATEDIF(M14,C45,"d") -> #NUM!
F33: =ROUNDUP(Total_Finance_Charge+SUM($E$29:$E$33),0) -> 7572 | G33: MODE OF PAYMENT: | I33: ='Master data Input'!F42 -> 0
A35: Net Proceeds | F35: =ROUNDUP(Principal_Amount-Total_Deduction,0) -> 73382 | M35: IF('Master data Input'!B35="YES",ROUNDUP(F16*0.0015,0),"0") | U35: DATEDIF(H11,I11,"D")
A37: Effective Rate (per month) | F37: ='Monthly -client copy'!F33 -> 0.037 | M37: IF(1200>O27,1200,O27)
A38: % of Finance charges to Total Amount Financed | F38: ='Monthly -client copy'!F32 -> 0.10852916 | G38: Release Date: | I38: =Date_Released -> 46083
G39: Agent: | H39: =UPPER(Agents)
A40: SCHEDULE OF AMORTIZATION
N41: =D43+E20 -> 14049.306 | O41: 11667
B42: Principal / Amount of Loan | D42: Interest Due on Loans | F42: Total Amount Payable | Z42: =DATE(YEAR(U21),MONTH(U21)+1,DAY(U21)) -> 31
C43: ='Monthly -client copy'!F67 -> 80953.71 | D43: =Total_InterestRate -> 14049.306 | F43: =C43+Total_UII -> 95003.016 | L43: =DATE(YEAR($C$45),MONTH($C$45)+($G$13-1),DAY($C$45)) -> 42986 | M43: w/out adjustment
B44: Period | C44: Due Date | D44: amortization | E44: Interest | G44: Principal | J44: Balance
B45: 1 | C45: 42651 | D45: =IF(PERIOD<>"",($F$43/$B$70),"") -> 7916.918 | E45: =IF(NOT(B45=AA27),$D$43*(($B$70-(B45-1))/((($B$70+1)/2)*$B$70)),"") -> 2161.4317 | G45: =D45-E45 -> 5755.4863 | J45: =C43-G45 -> 75198.224 | K45: =IF(WEEKDAY(L45,2)=1,"Monday",IF(WEEKDAY(L45,2)=2,"Tuesday",IF(WEEKDAY(L45,2)=3,"Wednesday",IF(WEEKDAY(L45,2)=4,"Thursday",IF(WEEKDAY(L45,2)=5,"Friday",IF(WEEKDAY(L45,2)=6,"Saturday",IF(WEEKDAY(L45,2)=7,"Sunday"))))))) -> Thursday | L45: ='Master data Input'!C30 -> 46128
B46: =IF(B45<$G$13,B45+1,"") -> 2 | C46: 42666 | D46: =IF(PERIOD<>"",($F$43/$B$70),"") -> 7916.918 | E46: =IF(NOT(B46=AA28),$D$43*(($B$70-(B46-1))/((($B$70+1)/2)*$B$70)),"") -> 1981.3124 | G46: =IF(NOT(B46=AA31),D46-E46,"") -> 5935.6056 | J46: =J45-G46 -> 69262.618 | K46: =IF(WEEKDAY(L46,2)=1,"Monday",IF(WEEKDAY(L46,2)=2,"Tuesday",IF(WEEKDAY(L46,2)=3,"Wednesday",IF(WEEKDAY(L46,2)=4,"Thursday",IF(WEEKDAY(L46,2)=5,"Friday",IF(WEEKDAY(L46,2)=6,"Saturday",IF(WEEKDAY(L46,2)=7,"Sunday"))))))) -> #VALUE! | L46: =IF(PERIOD<>"",IF(DATE(YEAR(L45),MONTH(L45),DAY(L45))<=$L$43,DATE(YEAR(L45),MONTH(L45)+1,DAY(L45)),""),"")
B47: =IF(B46<$G$13,B46+1,"") -> 3 | C47: 42682 | D47: =IF(PERIOD<>"",($F$43/$B$70),"") -> 7916.918 | E47: =IF(NOT(B47=AA31),$D$43*(($B$70-(B47-1))/((($B$70+1)/2)*$B$70)),"") -> 1801.1931 | G47: =IF(NOT(B47=AA33),D47-E47,"") -> 6115.7249 | J47: =J46-G47 -> 63146.893 | K47: =IF(WEEKDAY(L47,2)=1,"Monday",IF(WEEKDAY(L47,2)=2,"Tuesday",IF(WEEKDAY(L47,2)=3,"Wednesday",IF(WEEKDAY(L47,2)=4,"Thursday",IF(WEEKDAY(L47,2)=5,"Friday",IF(WEEKDAY(L47,2)=6,"Saturday",IF(WEEKDAY(L47,2)=7,"Sunday"))))))) -> #VALUE! | L47: =IF(PERIOD<>"",IF(DATE(YEAR(L46),MONTH(L46),DAY(L46))<=$L$43,DATE(YEAR(L46),MONTH(L46)+1,DAY(L46)),""),"") -> #VALUE!
B48: =IF(B47<$G$13,B47+1,"") -> 4 | C48: 42697 | D48: =IF(PERIOD<>"",($F$43/$B$70),"") -> 7916.918 | E48: =IF(NOT(B48=AA33),$D$43*(($B$70-(B48-1))/((($B$70+1)/2)*$B$70)),"") -> 1621.0738 | G48: =IF(NOT(B48=AA34),D48-E48,"") -> 6295.8442 | J48: =J47-G48 -> 56851.049 | K48: =IF(WEEKDAY(L48,2)=1,"Monday",IF(WEEKDAY(L48,2)=2,"Tuesday",IF(WEEKDAY(L48,2)=3,"Wednesday",IF(WEEKDAY(L48,2)=4,"Thursday",IF(WEEKDAY(L48,2)=5,"Friday",IF(WEEKDAY(L48,2)=6,"Saturday",IF(WEEKDAY(L48,2)=7,"Sunday"))))))) -> #VALUE! | L48: =IF(PERIOD<>"",IF(DATE(YEAR(L47),MONTH(L47),DAY(L47))<=$L$43,DATE(YEAR(L47),MONTH(L47)+1,DAY(L47)),""),"") -> #VALUE!
B49: =IF(B48<$G$13,B48+1,"") -> 5 | C49: 42712 | D49: =IF(PERIOD<>"",($F$43/$B$70),"") -> 7916.918 | E49: =IF(NOT(B49=AA34),$D$43*(($B$70-(B49-1))/((($B$70+1)/2)*$B$70)),"") -> 1440.9545 | G49: =IF(NOT(B49=AA35),D49-E49,"") -> 6475.9635 | J49: =J48-G49 -> 50375.085 | K49: =IF(WEEKDAY(L49,2)=1,"Monday",IF(WEEKDAY(L49,2)=2,"Tuesday",IF(WEEKDAY(L49,2)=3,"Wednesday",IF(WEEKDAY(L49,2)=4,"Thursday",IF(WEEKDAY(L49,2)=5,"Friday",IF(WEEKDAY(L49,2)=6,"Saturday",IF(WEEKDAY(L49,2)=7,"Sunday"))))))) -> #VALUE! | L49: =IF(PERIOD<>"",IF(DATE(YEAR(L48),MONTH(L48),DAY(L48))<=$L$43,DATE(YEAR(L48),MONTH(L48)+1,DAY(L48)),""),"") -> #VALUE!
...

Sheet Semi Monthly -client copy
A4: =UPPER("Computation Sheet and Payment Schedule") -> COMPUTATION SHEET AND PAYMENT SCHEDULE | K4: =DATEDIF(H8,Maturitydate,"D") -> 386 | L4: =Terms*30 -> 360
A5: NAME | C5: ADDRESS | E5: TYPE OF LOAN | H5: TERMS
A6: =IF(OR_NAME<>"",Client_Name &" or " & OR_NAME,Client_Name) -> ** or ** | C6: =PROPER('Master data Input'!C8) -> ** | F6: =Type_of_Loan&TEXT(IF(Express="YES","-EXPRESS",""),"") -> SML | H6: In months | I6: ='Master data Input'!K10 -> 12 | J6: =Terms -> 12
H7: from | I7: to
H8: =Date_Released_SM -> 43265 | I8: =Maturitydate_SM -> 43651 | M8: ='Master data Input'!F30 -> 46342 | N8: end of term | O8: =I6 -> 12
F9: # of payments | H9: ='Master data Input'!K12 -> 12
M10: =IF(U23<H8,H8,U23) -> 43265
A11: COMPUTATION OF NET PROCEEDS
W12: 7
A13: Principal/ Amount Financed | F13: =IF(get_loan_amount="NET AMOUNT",get_gross_amount,Loan_Amount) -> 80953.71
A14: Less: Deduction
A15: Interest | G15: New | I15: =Renewal -> No
B16: =Interest -> 0.03 | C16: ="from"&TEXT(Date_Released," mm/dd/yyyy")&" to "&TEXT(Date_released2," mm/dd/yyyy") -> from 03/02/2026 to 06/14/2018 | E16: =IF(upfront="YES",'Master data Input'!K24,IF(Type_of_Loan="BL-SA",0,ROUND(Principal_Amount*(Interest/30)*DATEDIF(Date_Released,'Monthly -client copy'!Date_released2,"d"),2))) -> 1214.31 | G16: Renewal Nth loan | I16: ='Master data Input'!F18 -> 0 | J16: =E16+C41/A41-(360/DATEDIF(H8,I8,"d")) -> 1213.5509 | L16: =DATEDIF(H8,B46,"d") -> #NUM! | M16: days from loan release and 1st payment
A17: Processing Fee | C17: =Processing_Fee_in_Percentage -> 0.075 | E17: =Principal_Amount*Percent_processingfee -> 6071.5283 | G17: Installment Type | I17: =Semi_Monthly_SM -> Monthly | L17: =DATEDIF(H8,M10,"D") -> 0
A18: Account Management Fee | E18: =Account_Management_fee -> Auto compute**
A19: Doc fee | E19: =Docfee_Yes_or_No -> 500
A20: Notarial fee | C20: =IF(L4<K4," NUMBER OF DAYS EXCEEDS","") -> NUMBER OF DAYS EXCEEDS | E20: =Notarial_Fee -> 500 | G20: Check No.
A21: ='Master data Input'!B42 -> MLRI -Insurance | E21: =Insurance -> Auto compute**
A22: ='Master data Input'!B45 -> Miscellaneous | E22: ='Master data Input'!C45 -> 500 | L22: =DATEDIF(M10,M8,"D") -> 3077
A23: Total Finance charge | E23: =SUM(E16:E22) -> 8785.8383 | G23: PN no. | H23: ="PN-"&TEXT('Master data Input'!F10,"0000- ")&TEXT(" "," ")&'Master data Input'!C14 -> PN-. SML | L23: =DATEDIF(H8,M8,"D") -> 3077 | U23: =DATE(YEAR(B46),MONTH(B46),DAY(B46)-30) -> 42643
A25: Others: | G25: Branch: | H25: ='Master data Input'!F38 -> 0 | P25: =TEXT($L$16,"0")&"/"&TEXT($L$17,"0")&"/"&TEXT($L$22,"0")&"/"&TEXT($L$23,"0") -> #NUM! | X25: =45000*0.15*(305/360) -> 5718.75
A26: =Cash_Advance -> Cash Advance | E26: =Advanced_Payment -> 0 | L26: =DATEDIF(M10,B46,"d") -> #NUM!
A27: ='Master data Input'!B12 -> Outstanding Balance from previous loan | E27: =Outstanding_Balance_from_previous_loan -> 0
F28: =Total_Finance_Charge+SUM($E$26:$E$28) -> 8785.8383
G29: MODE OF PAYMENT: | I29: ='Master data Input'!F42 -> 0
A30: Net Proceeds | F30: =Principal_Amount-Total_Deduction -> 72167.872
M31: IF('Master data Input'!B35="YES",ROUNDUP(F16*0.0015,0),"0") | U31: DATEDIF(H11,I11,"D")
A32: % of Finance charges to Total Amount Financed | F32: =Total_Finance_Charge/Principal_Amount -> 0.10852916
A33: Contractual Interest Rate per Month | F33: =Contractual_Rate -> 0.037
A34: Equivalent Add-on Interest Rate per Month | F34: =Interest -> 0.03
A35: Effective Annual Rate (EIR) | F35: =EIR -> 0.661088 | M35: IF(1200>O27,1200,O27)
A36: Effective Monthly Interest Rate (MIR) | F36: =MIR -> 0.065489269 | G36: Release Date: | I36: =Date_Released -> 46083
G37: Agent: | H37: =UPPER(Agents)
A38: SCHEDULE OF PAYMENT
N39: =C41+E16 -> 15263.616 | O39: 11667
A40: Principal / Amount of Loan | C40: Interest Due on Loans | E40: Total Amount Payable | X40: =DATE(YEAR(U17),MONTH(U17)+1,DAY(U17)) -> 31
A41: =Principal_Amount -> 80953.71 | C41: ='computation sheet'!C37 -> 14049.306 | E41: =IF(Type_of_Loan="BL-SA",Amount_of_Loan,Loan_Amount+Total_UII) -> 95003.016 | J41: =DATE(YEAR($B$46),MONTH($B$46)+($H$9-1),DAY($B$46)) -> 43008 | K41: w/out adjustment
A43: Period | B43: Due Date | C43: Gross Loan | D43: Amortization | E43: Interest | F43: Principal | G43: Other Charges | I43: Balance
C44: =Loan_Amount -> 80953.71 | I44: =Loan_Amount -> 80953.71
A45: 0 | G45: ='Semi Monthly -client copy'!Total_Deduction -> 8785.8383 | I45: =Loan_Amount -> 80953.71 | N45: =D61/12 -> 7916.918
...

Sheet Semi Monthly
A8: =UPPER("Computation Sheet and Payment Schedule") -> COMPUTATION SHEET AND PAYMENT SCHEDULE
A9: NAME | C9: ADDRESS | E9: TYPE OF LOAN | H9: TERMS
A10: =IF(OR_NAME<>"",Client_Name &" or " & OR_NAME,Client_Name) -> ** or ** | C10: =PROPER('Master data Input'!C8) -> ** | F10: =Type_of_Loan&TEXT(IF(Express="YES","-EXPRESS",""),"") -> SML | H10: In months | I10: =DATEDIF(Start_Payment,Maturitydate,"d")/30 -> 7.1333333 | J10: =Terms -> 7.1333333
F11: Interest/mo | G11: =Interest -> 0.03 | H11: from | I11: to
A12: =IF(UPPER(OR_NAME)<>" ",UPPER(OR_NAME),".") -> ** | H12: =Date_Released -> 46083 | I12: =MaturityDate_data_input -> 46342 | M12: ='Master data Input'!F30 -> 46342 | N12: end of term | O12: =I10 -> 7.1333333
F13: # of payments | G13: =Number_of_Amortization -> 8
M14: =IF(U27<H12,H12,U27) -> 46098
A15: COMPUTATION OF NET PROCEEDS
W16: 7
A17: Principal/ Amount Financed | F17: =Loan_Amount -> 80953.71
A19: Less Interest and Other Charges | G19: New | I19: =IF(I20>0,"NO", "YES") -> NO
A20: Interest | B20: =Interest -> 0.03 | C20: ="from"&TEXT(Date_Released," mm/dd/yyyy")&" to "&TEXT(Date_released2," mm/dd/yyyy") -> from 03/02/2026 to 03/17/2026 | E20: =IF(Type_of_Loan="BL-SA",ROUND(Principal_Amount*(Interest/30)*DATEDIF(Date_Released,MaturityDate1,"D"),0),ROUND(Principal_Amount*(Interest/30)*DATEDIF(Date_Released,Date_released2,"d"),0)) -> 1214 | G20: Renewal Nth loan | I20: ='Master data Input'!C18 -> No | J20: =E20+D43/B43-(360/DATEDIF(H12,I12,"d")) -> 1212.854 | L20: =DATEDIF(H12,C45,"d") -> 45 | M20: days from loan release and 1st payment
A21: Processing Fee | C21: =Processing_Fee_in_Percentage -> 0.075 | E21: =Processing_Fee_in_Percentage*Principal_Amount -> 6071.5283 | G21: Installment Type | I21: =Installment_Type -> Monthly | L21: =DATEDIF(H12,M14,"D") -> 15
A22: Account Management Fee | E22: =Account_Management_fee -> Auto compute**
A23: Notarial fee | E23: =Notarial_Fee -> 500
A24: Doc fee | E24: =IF(Docfee_Yes_or_No="YES",ROUNDUP(Principal_Amount/200,0),0) -> 0
A25: ='Master data Input'!B42 -> MLRI -Insurance | E25: =Insurance -> Auto compute**
A26: ='Master data Input'!B45 -> Miscellaneous | E26: ='Master data Input'!C45 -> 500 | G26: Check No. | L26: =DATEDIF(M14,M12,"D") -> 244
A27: Total Finance charge | E27: =SUM(E20:E26) -> 8285.5282 | L27: =DATEDIF(H12,M12,"D") -> 259 | U27: =DATE(YEAR(C45),MONTH(C45),DAY(C45)-30) -> 46098
A28: Others: | G28: PN no. | H28: ="PN-"&TEXT('Master data Input'!F10,"0000- ")&TEXT(" "," ")&'Master data Input'!C14 -> PN-. SML
A29: ='Master data Input'!B12 -> Outstanding Balance from previous loan | E29: =Outstanding_Balance_from_previous_loan -> 0 | P29: =TEXT($L$20,"0")&"/"&TEXT($L$21,"0")&"/"&TEXT($L$26,"0")&"/"&TEXT($L$27,"0") -> 45/15/244/259 | X29: =45000*0.15*(305/360) -> 5718.75
A30: Cash Advanced | E30: =Advanced_Payment -> 0 | L30: =DATEDIF(M14,C45,"d") -> 30
F33: =Total_Finance_Charge+SUM($E$29:$E$33) -> 8285.5282 | G33: MODE OF PAYMENT: | I33: ='Master data Input'!F42 -> 0
A35: Net Proceeds | F35: =Principal_Amount-Total_Deduction -> 72668.182 | M35: IF('Master data Input'!B35="YES",ROUNDUP(F16*0.0015,0),"0") | U35: DATEDIF(H11,I11,"D")
A37: Effective Rate (per month) | F37: =IF(Grace_Period_Interest=0,(Grace_Period_Interest+Total_UII)/Amount_of_Loan/(DATEDIF(Date_Released,MaturityDate1,"d")/30),(Grace_Period_Interest+Total_UII)/Amount_of_Loan/Term_masterdatainput) -> 0.032374983 | M37: IF(1200>O27,1200,O27)
A38: % of Finance charges to Total Amount Financed | F38: =Total_Finance_Charge/Principal_Amount -> 0.10234896 | G38: Release Date: | I38: =Date_Released -> 46083
G39: Agent: | H39: =UPPER(Agents)
A40: SCHEDULE OF AMORTIZATION
N41: =D43+E20 -> 20967 | O41: 11667
B42: Principal / Amount of Loan | D42: Interest Due on Loans | F42: Total Amount Payable | Y42: =DATE(YEAR(U21),MONTH(U21)+1,DAY(U21)) -> 31
B43: =Principal_Amount -> 80953.71 | D43: =IF(Type_of_Loan="BL-SA",0,IF(Type_of_Loan="QCL",(Principal_Amount*Interest*Term_masterdatainput),ROUND(Principal_Amount*(Interest/30)*DATEDIF(Date_released2,MaturityDate1,"d"),0))) -> 19753 | F43: =IF(Type_of_Loan="BL-SA",Amount_of_Loan,Loan_Amount+Total_UII) -> 100706.71 | K43: =DATE(YEAR($C$45),MONTH($C$45)+($G$13-1),DAY($C$45)) -> 46342 | L43: w/out adjustment
B44: Period | C44: Due Date | D44: amortization | E44: Prepared/ Verified by: | S44: Interest | U44: Principal
B45: 1 | C45: =Start_Payment -> 46128 | D45: =D70-SUM(D46:D69) -> 12590.71 | S45: =IF(NOT(B45=AA27),$D$43*(($B$70-(B45-1))/((($B$70+1)/2)*$B$70)),"") -> 4389.5556 | U45: =IF(NOT(B45=AA28),D45-S45,"") -> 8201.1544 | X45: =IF(WEEKDAY(Y45,2)=1,"Monday",IF(WEEKDAY(Y45,2)=2,"Tuesday",IF(WEEKDAY(Y45,2)=3,"Wednesday",IF(WEEKDAY(Y45,2)=4,"Thursday",IF(WEEKDAY(Y45,2)=5,"Friday",IF(WEEKDAY(Y45,2)=6,"Saturday",IF(WEEKDAY(Y45,2)=7,"Sunday"))))))) -> Thursday | Y45: ='Master data Input'!C30 -> 46128
B46: =IF(B45<$G$13,B45+1,"") -> 2 | C46: =IF(PERIOD<>"",DATE(YEAR(C45),MONTH(C45),DAY(C45)+15),"") -> 46143 | D46: =IF(PERIOD<>"",ROUNDDOWN($F$43/$B$70,0),"") -> 12588 | S46: =IF(NOT(B46=AA28),$D$43*(($B$70-(B46-1))/((($B$70+1)/2)*$B$70)),"") -> 3840.8611 | U46: =IF(NOT(B46=AA31),D46-S46,"") -> 8747.1389 | X46: =IF(WEEKDAY(Y46,2)=1,"Monday",IF(WEEKDAY(Y46,2)=2,"Tuesday",IF(WEEKDAY(Y46,2)=3,"Wednesday",IF(WEEKDAY(Y46,2)=4,"Thursday",IF(WEEKDAY(Y46,2)=5,"Friday",IF(WEEKDAY(Y46,2)=6,"Saturday",IF(WEEKDAY(Y46,2)=7,"Sunday"))))))) -> Saturday | Y46: =IF(PERIOD<>"",IF(DATE(YEAR(Y45),MONTH(Y45),DAY(Y45))<=$K$43,DATE(YEAR(Y45),MONTH(Y45)+1,DAY(Y45)),""),"") -> 46158
B47: =IF(B46<$G$13,B46+1,"") -> 3 | C47: 40918 | D47: =IF(PERIOD<>"",ROUNDDOWN($F$43/$B$70,0),"") -> 12588 | E47: Noted by: | S47: =IF(NOT(B47=AA31),$D$43*(($B$70-(B47-1))/((($B$70+1)/2)*$B$70)),"") -> 3292.1667 | U47: =IF(NOT(B47=AA33),D47-S47,"") -> 9295.8333 | X47: =IF(WEEKDAY(Y47,2)=1,"Monday",IF(WEEKDAY(Y47,2)=2,"Tuesday",IF(WEEKDAY(Y47,2)=3,"Wednesday",IF(WEEKDAY(Y47,2)=4,"Thursday",IF(WEEKDAY(Y47,2)=5,"Friday",IF(WEEKDAY(Y47,2)=6,"Saturday",IF(WEEKDAY(Y47,2)=7,"Sunday"))))))) -> Tuesday | Y47: =IF(PERIOD<>"",IF(DATE(YEAR(Y46),MONTH(Y46),DAY(Y46))<=$K$43,DATE(YEAR(Y46),MONTH(Y46)+1,DAY(Y46)),""),"") -> 46189
B48: =IF(B47<$G$13,B47+1,"") -> 4 | C48: 40933 | D48: =IF(PERIOD<>"",ROUNDDOWN($F$43/$B$70,0),"") -> 12588 | S48: =IF(NOT(B48=AA33),$D$43*(($B$70-(B48-1))/((($B$70+1)/2)*$B$70)),"") -> 2743.4722 | U48: =IF(NOT(B48=AA34),D48-S48,"") -> 9844.5278 | X48: =IF(WEEKDAY(Y48,2)=1,"Monday",IF(WEEKDAY(Y48,2)=2,"Tuesday",IF(WEEKDAY(Y48,2)=3,"Wednesday",IF(WEEKDAY(Y48,2)=4,"Thursday",IF(WEEKDAY(Y48,2)=5,"Friday",IF(WEEKDAY(Y48,2)=6,"Saturday",IF(WEEKDAY(Y48,2)=7,"Sunday"))))))) -> Thursday | Y48: =IF(PERIOD<>"",IF(DATE(YEAR(Y47),MONTH(Y47),DAY(Y47))<=$K$43,DATE(YEAR(Y47),MONTH(Y47)+1,DAY(Y47)),""),"") -> 46219
B49: =IF(B48<$G$13,B48+1,"") -> 5 | C49: =IF(PERIOD<>"",DATE(YEAR(C48),MONTH(C48),DAY(C48)+15),"") -> 40948 | D49: =IF(PERIOD<>"",ROUNDDOWN($F$43/$B$70,0),"") -> 12588 | S49: =IF(NOT(B49=AA34),$D$43*(($B$70-(B49-1))/((($B$70+1)/2)*$B$70)),"") -> 2194.7778 | U49: =IF(NOT(B49=AA35),D49-S49,"") -> 10393.222 | X49: =IF(WEEKDAY(Y49,2)=1,"Monday",IF(WEEKDAY(Y49,2)=2,"Tuesday",IF(WEEKDAY(Y49,2)=3,"Wednesday",IF(WEEKDAY(Y49,2)=4,"Thursday",IF(WEEKDAY(Y49,2)=5,"Friday",IF(WEEKDAY(Y49,2)=6,"Saturday",IF(WEEKDAY(Y49,2)=7,"Sunday"))))))) -> Sunday | Y49: =IF(PERIOD<>"",IF(DATE(YEAR(Y48),MONTH(Y48),DAY(Y48))<=$K$43,DATE(YEAR(Y48),MONTH(Y48)+1,DAY(Y48)),""),"") -> 46250
B50: =IF(B49<$G$13,B49+1,"") -> 6 | C50: =IF(PERIOD<>"",DATE(YEAR(C49),MONTH(C49),DAY(C49)+15),"") -> 40963 | D50: =IF(PERIOD<>"",ROUNDDOWN($F$43/$B$70,0),"") -> 12588 | E50: Released by: | S50: =IF(NOT(B50=AA35),$D$43*(($B$70-(B50-1))/((($B$70+1)/2)*$B$70)),"") -> 1646.0833 | U50: =IF(NOT(B50=AA36),D50-S50,"") -> 10941.917 | X50: =IF(WEEKDAY(Y50,2)=1,"Monday",IF(WEEKDAY(Y50,2)=2,"Tuesday",IF(WEEKDAY(Y50,2)=3,"Wednesday",IF(WEEKDAY(Y50,2)=4,"Thursday",IF(WEEKDAY(Y50,2)=5,"Friday",IF(WEEKDAY(Y50,2)=6,"Saturday",IF(WEEKDAY(Y50,2)=7,"Sunday"))))))) -> Wednesday | Y50: =IF(PERIOD<>"",IF(DATE(YEAR(Y49),MONTH(Y49),DAY(Y49))<=$K$43,DATE(YEAR(Y49),MONTH(Y49)+1,DAY(Y49)),""),"") -> 46281
B51: =IF(B50<$G$13,B50+1,"") -> 7 | C51: =IF(PERIOD<>"",DATE(YEAR(C50),MONTH(C50),DAY(C50)+15),"") -> 40978 | D51: =IF(PERIOD<>"",ROUNDDOWN($F$43/$B$70,0),"") -> 12588 | S51: =IF(NOT(B51=AA36),$D$43*(($B$70-(B51-1))/((($B$70+1)/2)*$B$70)),"") -> 1097.3889 | U51: =IF(NOT(B51=AA37),D51-S51,"") -> 11490.611 | X51: =IF(WEEKDAY(Y51,2)=1,"Monday",IF(WEEKDAY(Y51,2)=2,"Tuesday",IF(WEEKDAY(Y51,2)=3,"Wednesday",IF(WEEKDAY(Y51,2)=4,"Thursday",IF(WEEKDAY(Y51,2)=5,"Friday",IF(WEEKDAY(Y51,2)=6,"Saturday",IF(WEEKDAY(Y51,2)=7,"Sunday"))))))) -> Friday | Y51: =IF(PERIOD<>"",IF(DATE(YEAR(Y50),MONTH(Y50),DAY(Y50))<=$K$43,DATE(YEAR(Y50),MONTH(Y50)+1,DAY(Y50)),""),"") -> 46311
B52: =IF(B51<$G$13,B51+1,"") -> 8 | C52: =IF(PERIOD<>"",DATE(YEAR(C51),MONTH(C51),DAY(C51)+15),"") -> 40993 | D52: =IF(PERIOD<>"",ROUNDDOWN($F$43/$B$70,0),"") -> 12588 | S52: =IF(NOT(B52=AA37),$D$43*(($B$70-(B52-1))/((($B$70+1)/2)*$B$70)),"") -> 548.69444 | U52: =IF(NOT(B52=AA38),D52-S52,"") -> 12039.306 | X52: =IF(WEEKDAY(Y52,2)=1,"Monday",IF(WEEKDAY(Y52,2)=2,"Tuesday",IF(WEEKDAY(Y52,2)=3,"Wednesday",IF(WEEKDAY(Y52,2)=4,"Thursday",IF(WEEKDAY(Y52,2)=5,"Friday",IF(WEEKDAY(Y52,2)=6,"Saturday",IF(WEEKDAY(Y52,2)=7,"Sunday"))))))) -> Monday | Y52: =IF(PERIOD<>"",IF(DATE(YEAR(Y51),MONTH(Y51),DAY(Y51))<=$K$43,DATE(YEAR(Y51),MONTH(Y51)+1,DAY(Y51)),""),"") -> 46342
...

Sheet 48 payments (computation)semi
A4: 9th Floor Times Plaza Bldg., UN Ave. Cor. Taft Ave. Ermita Manila
A5: Manila, Philippines
A6: 353-85-24/25
A7: =UPPER("Computation Sheet and Payment Schedule") -> COMPUTATION SHEET AND PAYMENT SCHEDULE
A8: NAME | C8: ADDRESS | E8: TYPE OF LOAN | H8: TERMS
A9: =IF(OR_NAME<>"",Client_Name &" or " & OR_NAME,Client_Name) -> ** or ** | C9: =PROPER('Master data Input'!C8) -> ** | F9: =Type_of_Loan&TEXT(IF(Express="YES","-EXPRESS",""),"") -> SML | H9: In months | I9: =DATEDIF(Start_Payment,Maturitydate,"d")/30 -> 7.1333333 | J9: =Terms -> 7.1333333
F10: Interest/mo | G10: =Interest -> 0.03 | H10: from | I10: to
A11: =IF(UPPER(OR_NAME)<>" ",UPPER(OR_NAME),".") -> ** | H11: =Date_Released -> 46083 | I11: =MaturityDate_data_input -> 46342 | M11: ='Master data Input'!F30 -> 46342 | N11: end of term | O11: =I9 -> 7.1333333
F12: # of payments | G12: =Number_of_Amortization -> 8
M13: =IF(U26<H11,H11,U26) -> 46098
A14: COMPUTATION OF NET PROCEEDS
W15: 7
A16: Principal/ Amount Financed | F16: =Loan_Amount -> 80953.71
A18: Less Interest and Other Charges | G18: New | I18: =IF(I19>0,"NO", "YES") -> NO
A19: Interest | B19: =Interest -> 0.03 | C19: ="from"&TEXT(Date_Released," mm/dd/yyyy")&" to "&TEXT(Date_released2," mm/dd/yyyy") -> from 03/02/2026 to 03/17/2026 | E19: =IF(Type_of_Loan="BL-SA",ROUND(Principal_Amount*(Interest/30)*DATEDIF(Date_Released,MaturityDate1,"D"),0),ROUND(Principal_Amount*(Interest/30)*DATEDIF(Date_Released,Date_released2,"d"),0)) -> 1214 | G19: Renewal Nth loan | I19: ='Master data Input'!C18 -> No | J19: =E19+D42/B42-(360/DATEDIF(H11,I11,"d")) -> 1212.854 | L19: =DATEDIF(H11,C44,"d") -> 45 | M19: days from loan release and 1st payment
A20: Processing Fee | C20: =Processing_Fee_in_Percentage -> 0.075 | E20: =Processing_Fee_in_Percentage*Principal_Amount -> 6071.5283 | G20: Installment Type | I20: =Installment_Type -> Monthly | L20: =DATEDIF(H11,M13,"D") -> 15
A21: Account Management Fee | E21: =Account_Management_fee -> Auto compute**
A22: Notarial fee | E22: =Notarial_Fee -> 500
A23: Doc fee | E23: =IF(Docfee_Yes_or_No="YES",ROUNDUP(Principal_Amount/200,0),0) -> 0
A24: ='Master data Input'!B42 -> MLRI -Insurance | E24: =Insurance -> Auto compute**
A25: ='Master data Input'!B45 -> Miscellaneous | E25: ='Master data Input'!C45 -> 500 | G25: Check No. | L25: =DATEDIF(M13,M11,"D") -> 244
A26: Total Finance charge | E26: =SUM(E19:E25) -> 8285.5282 | L26: =DATEDIF(H11,M11,"D") -> 259 | U26: =DATE(YEAR(C44),MONTH(C44),DAY(C44)-30) -> 46098
G27: PN no. | H27: ="PN-"&TEXT('Master data Input'!F10,"0000- ")&TEXT(" "," ")&'Master data Input'!C14 -> PN-. SML
A28: Others: | P28: =TEXT($L$19,"0")&"/"&TEXT($L$20,"0")&"/"&TEXT($L$25,"0")&"/"&TEXT($L$26,"0") -> 45/15/244/259 | X28: =45000*0.15*(305/360) -> 5718.75
A29: ='Master data Input'!B12 -> Outstanding Balance from previous loan | E29: =Outstanding_Balance_from_previous_loan -> 0 | L29: =DATEDIF(M13,C44,"d") -> 30
A30: Cash Advanced | E30: =Advanced_Payment -> 0
F32: =Total_Finance_Charge+SUM($E$29:$E$32) -> 8285.5282 | G32: MODE OF PAYMENT: | I32: ='Master data Input'!F42 -> 0
A34: Net Proceeds | F34: =Principal_Amount-Total_Deduction -> 72668.182 | M34: IF('Master data Input'!B35="YES",ROUNDUP(F16*0.0015,0),"0") | U34: DATEDIF(H11,I11,"D")
A36: Effective Rate (per month) | F36: =IF(Grace_Period_Interest=0,(Grace_Period_Interest+Total_UII)/Amount_of_Loan/(DATEDIF(Date_Released,MaturityDate1,"d")/30),(Grace_Period_Interest+Total_UII)/Amount_of_Loan/Term_masterdatainput) -> 0.032374983 | M36: IF(1200>O27,1200,O27)
A37: % of Finance charges to Total Amount Financed | F37: =Total_Finance_Charge/Principal_Amount -> 0.10234896 | G37: Release Date: | I37: =Date_Released -> 46083
G38: Agent: | H38: =UPPER(Agents)
A39: SCHEDULE OF AMORTIZATION
N40: =D42+E19 -> 20967 | O40: 11667
B41: Principal / Amount of Loan | D41: Interest Due on Loans | F41: Total Amount Payable | Y41: =DATE(YEAR(U20),MONTH(U20)+1,DAY(U20)) -> 31
B42: =Principal_Amount -> 80953.71 | D42: =IF(Type_of_Loan="BL-SA","",IF(Type_of_Loan="QCL",(Principal_Amount*Interest*Term_masterdatainput),ROUND(Principal_Amount*(Interest/30)*DATEDIF(Date_released2,MaturityDate1,"d"),0))) -> 19753 | F42: =IF(Type_of_Loan="BL-SA",Amount_of_Loan,Loan_Amount+Total_UII) -> 100706.71 | K42: =DATE(YEAR($C$44),MONTH($C$44)+($G$12-1),DAY($C$44)) -> 46342 | L42: w/out adjustment
B43: Period | C43: Due Date | D43: amortization | E43: Prepared/ Verified by: | S43: Interest | U43: Principal
B44: 1 | C44: =Start_Payment -> 46128 | D44: =D92-SUM(D45:D91) -> 12590.71 | S44: =IF(NOT(B44=AA26),$D$42*(($B$92-(B44-1))/((($B$92+1)/2)*$B$92)),"") -> 4389.5556 | U44: =IF(NOT(B44=AA27),D44-S44,"") -> 8201.1544 | X44: =IF(WEEKDAY(Y44,2)=1,"Monday",IF(WEEKDAY(Y44,2)=2,"Tuesday",IF(WEEKDAY(Y44,2)=3,"Wednesday",IF(WEEKDAY(Y44,2)=4,"Thursday",IF(WEEKDAY(Y44,2)=5,"Friday",IF(WEEKDAY(Y44,2)=6,"Saturday",IF(WEEKDAY(Y44,2)=7,"Sunday"))))))) -> Thursday | Y44: ='Master data Input'!C30 -> 46128
B45: =IF(B44<$G$12,B44+1,"") -> 2 | C45: =IF(PERIOD<>"",DATE(YEAR(C44),MONTH(C44),DAY(C44)+15),"") -> 46143 | D45: =IF(PERIOD<>"",ROUNDDOWN($F$42/$B$92,0),"") -> 12588 | S45: =IF(NOT(B45=AA27),$D$42*(($B$92-(B45-1))/((($B$92+1)/2)*$B$92)),"") -> 3840.8611 | U45: =IF(NOT(B45=AA30),D45-S45,"") -> 8747.1389 | X45: =IF(WEEKDAY(Y45,2)=1,"Monday",IF(WEEKDAY(Y45,2)=2,"Tuesday",IF(WEEKDAY(Y45,2)=3,"Wednesday",IF(WEEKDAY(Y45,2)=4,"Thursday",IF(WEEKDAY(Y45,2)=5,"Friday",IF(WEEKDAY(Y45,2)=6,"Saturday",IF(WEEKDAY(Y45,2)=7,"Sunday"))))))) -> Friday | Y45: =IF(PERIOD<>"",IF(DATE(YEAR(Y44),MONTH(Y44),DAY(Y44))<=$K$42,DATE(YEAR(Y44),MONTH(Y44),DAY(Y44)+15),""),"") -> 46143
B46: =IF(B45<$G$12,B45+1,"") -> 3 | C46: =IF(PERIOD<>"",DATE(YEAR(C45),MONTH(C45),DAY(C45)+15),"") -> 46158 | D46: =IF(PERIOD<>"",ROUNDDOWN($F$42/$B$92,0),"") -> 12588 | E46: Noted by: | S46: =IF(NOT(B46=AA30),$D$42*(($B$92-(B46-1))/((($B$92+1)/2)*$B$92)),"") -> 3292.1667 | U46: =IF(NOT(B46=AA32),D46-S46,"") -> 9295.8333 | X46: =IF(WEEKDAY(Y46,2)=1,"Monday",IF(WEEKDAY(Y46,2)=2,"Tuesday",IF(WEEKDAY(Y46,2)=3,"Wednesday",IF(WEEKDAY(Y46,2)=4,"Thursday",IF(WEEKDAY(Y46,2)=5,"Friday",IF(WEEKDAY(Y46,2)=6,"Saturday",IF(WEEKDAY(Y46,2)=7,"Sunday"))))))) -> Saturday | Y46: =IF(PERIOD<>"",IF(DATE(YEAR(Y45),MONTH(Y45),DAY(Y45))<=$K$42,DATE(YEAR(Y45),MONTH(Y45),DAY(Y45)+15),""),"") -> 46158
B47: =IF(B46<$G$12,B46+1,"") -> 4 | C47: =IF(PERIOD<>"",DATE(YEAR(C46),MONTH(C46),DAY(C46)+15),"") -> 46173 | D47: =IF(PERIOD<>"",ROUNDDOWN($F$42/$B$92,0),"") -> 12588 | S47: =IF(NOT(B47=AA32),$D$42*(($B$92-(B47-1))/((($B$92+1)/2)*$B$92)),"") -> 2743.4722 | U47: =IF(NOT(B47=AA33),D47-S47,"") -> 9844.5278 | X47: =IF(WEEKDAY(Y47,2)=1,"Monday",IF(WEEKDAY(Y47,2)=2,"Tuesday",IF(WEEKDAY(Y47,2)=3,"Wednesday",IF(WEEKDAY(Y47,2)=4,"Thursday",IF(WEEKDAY(Y47,2)=5,"Friday",IF(WEEKDAY(Y47,2)=6,"Saturday",IF(WEEKDAY(Y47,2)=7,"Sunday"))))))) -> Sunday | Y47: =IF(PERIOD<>"",IF(DATE(YEAR(Y46),MONTH(Y46),DAY(Y46))<=$K$42,DATE(YEAR(Y46),MONTH(Y46),DAY(Y46)+15),""),"") -> 46173
...

Sheet Sheet3
A1: 1 | B1: ='Semi Monthly 3 SL'!G13 -> 12 | I1: sheet
A2: 2 | B2: =B1-1 -> 11
A3: 3 | B3: =B2-1 -> 10
A4: 4 | B4: =B3-1 -> 9
A5: 5 | B5: =B4-1 -> 8
A6: 6 | B6: =B5-1 -> 7
A7: 7 | B7: =B6-1 -> 6
A8: 8 | B8: =B7-1 -> 5
A9: 9 | B9: =B8-1 -> 4
A10: 10 | B10: =B9-1 -> 3
A11: 11 | B11: =B10-1 -> 2
A12: 12 | B12: =B11-1 -> 1
A13: 13 | B13: =B12-1 -> 0
... A29: 29 | B29: =B28-1 -> -16
A30: 30
A31: 31
A32: 32
A33: 33
A34: 34
A35: 35
A36: 36
A37: 37
A38: 38
A39: 39
A40: 40
A41: 41
... A99: 99

Sheet Agent
A1: ONLINE (WEBSITE)
A2: WALK IN
A3: ALICIA SAAVEDRA
A4: CARMELITA DUMA
A5: DELIA OLARTE
A6: EDGAR LAGUITAN
A7: ELISA LAGUITAN
A8: EMELINDA PARAISO
A9: ERMELITO NAPOLEON
A10: EVANGELINE DETERA
A11: FABIOLITA BASAY
A12: FREDERICK MARCELO
... A30: ZENAIDA CABRIDO

Sheet Sheet1
A2: LIST OF AGENTS

Sheet parameter
A1: GROSS AMOUNT | C1: Add amount | K1: TERM | L1: ADD ON | M1: CONTRACTUAL | N1: x12
A2: NET AMOUNT | C2: MLRI | D2: AMF(reg) | E2: DOCUMENTATION FEE | G2: AMF(bl-sa) | H2: %AMF(reg) | I2: NOTARIAL | K2: 1 | L2: 3 | M2: 3 | N2: =M2*12 -> 36
C3: 400 | D3: 500 | E3: 400 | G3: 1000 | H3: 0.02 | I3: 500 | K3: 2 | L3: 3 | M3: 3.98 | N3: =M3*12 -> 47.76
K4: 3 | L4: 3 | M4: 4.43 | N4: =M4*12 -> 53.16
K5: 4 | L5: 3 | M5: 4.7 | N5: =M5*12 -> 56.4
K6: 5 | L6: 3 | M6: 4.85 | N6: =M6*12 -> 58.2
K7: 6 | L7: 3 | M7: 4.95 | N7: =M7*12 -> 59.4
K8: 7 | L8: 3 | M8: 5.01 | N8: =M8*12 -> 60.12
K9: 8 | L9: 3 | M9: 5.05 | N9: =M9*12 -> 60.6
K10: 9 | L10: 3 | M10: 5.07 | N10: =M10*12 -> 60.84
K11: 10 | L11: 3 | M11: 5.08 | N11: =M11*12 -> 60.96
K12: 11 | L12: 3 | M12: 5.08 | N12: =M12*12 -> 60.96
K13: 12 | L13: 3 | M13: 5.08 | N13: =M13*12 -> 60.96
K15: 1 | L15: 3.5 | M15: 3.5 | N15: =M15*12 -> 42
K16: 2 | L16: 3.5 | M16: 4.63 | N16: =M16*12 -> 55.56
... K78: 12 | L78: 2.5 | M78: 4.28 | N78: =M78*12 -> 51.36

Sheet Get Gross (2)
A2: Loan Type | D2: BL-SA
A3: Net Amount | D3: 300000
A4: Add on Rate | C4: 0.0275
A5: Processing fee | C5: 0.06
A6: Term | C6: 6
A8: Notarial | C8: =para_add_notarial -> 500
A9: Account Management fee | C9: =IF(D2="BL-SA",para_blsa_amf,2%/D20+para_add_amf_others) -> 1000
A10: MLRI Insurance | B10: Yes | C10: =IF(B10="Yes",get_gross_net_amount/1000*get_gross_term+para_add_mlri,0) -> 2200
A11: Documentation fee | C11: =get_gross_net_amount/200+para_add_doc -> 1900
A12: Others:
A16: TOTAL Charges | D16: =SUM(C8:C14) -> 5600
C17: Gross Loan = Numerator/Denominator | D17: =get_gross_net_amount+D16 -> 305600 | E17: (numerator)
D18: =100%-C5 -> 0.94 | E18: (denominator)
C20: Gross Loan = | D20: =D17/D18 -> 325106.38
C23: Total OB = | D23: =D20*C4*get_gross_term+D20 -> 378748.94

Sheet Parameter (2)
A1: Additional Fee (BLSA) | F1: Additional Fee (OTHERS)
A2: MLRI | B2: NOTARIAL | C2: DOCUMENTATION | D2: BLSA-AMF | G2: TOTAL OB | H2: Others | J2: Yes
A3: 400 | B3: 500 | C3: 400 | D3: 1000 | G3: 1000 | H3: 500 | J3: No
